Workbook

Sheet Dashboard
A1: ZATCA VAT Inspection Pack – Dashboard
A2: ="Company: "&Setup!B4&" | VAT No: "&Setup!B5&" | Period: "&TEXT(Setup!C19,"dd-mmm-yyyy")&" to "&TEXT(MAX(Setup!D19:D30),"dd-mmm-yyyy")&" | Filing: "&Setup!B8
A3: Indicator | B3: Value (SAR) | C3: Status | D3: What it means
A4: 1. Sales & Revenue
A5: Total sales per VAT returns (Box 6) | B5: =Recon_Sales!E88
A6: Revenue subject to VAT per Trial Balance | B6: =Recon_Sales!E87
A7: Unexplained revenue difference | B7: =Recon_Sales!E96 | C7: =IF(ABS(B7)<=Setup!$B$10,"✓ Reconciled","✗ Explain") | D7: ZATCA treats unexplained excess revenue as undeclared taxable sales
A8: Sales periods/boxes not matched | B8: =COUNTIF(Recon_Sales!H6:H17,"✗*")+COUNTIF(Recon_Sales!H22:H33,"✗*")+COUNTIF(Recon_Sales!H38:H49,"✗*")+COUNTIF(Recon_Sales!H54:H65,"✗*")+COUNTIF(Recon_Sales!H70:H81,"✗*") | C8: =IF(B8=0,"✓ None","✗ Review Recon_Sales")
A9: 2. Output VAT
A10: Output VAT per returns | B10: =Recon_OutputVAT!C17
A11: Output VAT per GL | B11: =Recon_OutputVAT!H17
A12: Potential under-declared output VAT | B12: =Recon_OutputVAT!M17 | C12: =IF(B12<=Setup!$B$10,"✓ None","✗ Exposure") | D12: Higher of register or GL above the return, per period
A13: 3. Input VAT
A14: Input VAT claimed per returns | B14: =Recon_InputVAT!C17
A15: Defensible input VAT per register | B15: =Recon_InputVAT!E17
A16: Potential over-claimed input VAT | B16: =Recon_InputVAT!K17 | C16: =IF(B16<=Setup!$B$10,"✓ None","✗ Exposure") | D16: Claimed in return but not supported by a valid, non-blocked invoice
A17: 4. VAT Account, Filing & Payment
A18: Returns filed late | B18: =COUNTIF(VAT_Returns!AT6:AT17,"✗*") | C18: =IF(B18=0,"✓ None","✗ Late")
A19: Return arithmetic errors | B19: =COUNTIF(VAT_Returns!AS6:AS17,"✗*") | C19: =IF(B19=0,"✓ None","✗ Check")
A20: VAT unpaid (outstanding) | B20: =Recon_VAT_Account!G18 | C20: =IF(B20<=Setup!$B$10,"✓ Settled","✗ Unpaid")
A21: GL VAT account periods not agreeing | B21: =COUNTIF(Recon_VAT_Account!O6:O17,"✗*") | C21: =IF(B21=0,"✓ None","✗ Investigate")
A22: Est. late payment penalties | B22: =Recon_VAT_Account!I18+Recon_VAT_Account!J18 | D22: 5% per month or part on late / unpaid tax
A23: 5. Data Quality
A24: Sales rows with exceptions | B24: =Sales_Register!B3 | C24: =IF(B24=0,"✓ Clean","✗ Review flags")
A25: Purchase rows with exceptions | B25: =Purchase_Register!B3 | C25: =IF(B25=0,"✓ Clean","✗ Review flags")
A26: TB months out of balance | B26: =COUNTIF(TB_Monthly!E3:S3,"<>0") | C26: =IF(B26=0,"✓ Balanced","✗ Fix TB")
A27: TB accounts without VAT mapping | B27: =SUMPRODUCT((TB_Monthly!A6:A505<>"")*(TB_Monthly!D6:D505="")) | C27: =IF(B27=0,"✓ All mapped","✗ Map accounts")
A28: Document checklist readiness | B28: =Checklist!F3 | C28: =IF(B28>=1,"✓ Ready","✗ Incomplete")
A29: 6. Indicative Exposure (before objection / penalty relief)
A30: Tax exposure (under-declared + over-claimed + unexplained revenue × rate) | B30: =B12+B16+MAX(0,B7)*Setup!$B$9 | D30: Unexplained revenue (TB > returns) × 15%. Indicative only
A31: Incorrect-return penalty on tax exposure | B31: =B30*Setup!$B$13 | D31: Art. 42 – 50% of the difference (indicative)
A32: Late payment penalties (est.) | B32: =B22
A33: TOTAL INDICATIVE EXPOSURE | B33: =B30+B31+B22 | C33: =IF(B33<=Setup!$B$10,"✓ Low risk","✗ Prepare defence / consider voluntary disclosure")
A35: Legend: yellow cells with blue text = inputs · grey = formulas · green text = links to other sheets · ✓ = OK · ✗ = needs action. All amounts in SAR. Example rows (Jan 2025) are included to show the format – overwrite them with your data.

Sheet Setup
A1: Setup – Company & Audit Period
A2: Yellow cells with blue text are inputs. Everything else in the workbook is driven by these settings.
A3: Setting | B3: Value | C3: Check / Note
A4: Company Name (اسم المنشأة) | B4: Example Trading Company | C4: Your legal name as on the VAT certificate
A5: VAT Registration No (الرقم الضريبي) | B5: 300000000000003 | C5: =IF(AND(LEN(B5)=15,LEFT(B5,1)="3",RIGHT(B5,1)="3",ISNUMBER(--B5)),"✓ Valid format","✗ Invalid VAT number format")
A6: Commercial Registration No | B6: 1010000000
A7: Fiscal Year Start (audit year) | B7: 45658 | C7: First day of the year under inspection
A8: Filing Frequency | B8: Monthly | C8: Monthly if taxable supplies > SAR 40M/yr, otherwise Quarterly
A9: Standard VAT Rate | B9: 0.15 | C9: 15% since 1 July 2020
A10: Variance Tolerance (SAR) | B10: 10 | C10: Differences within this amount are treated as rounding
A11: As-of Date (for penalty estimates) | B11: 46299 | C11: Usually today's date or the inspection date
A12: Late Payment Penalty (per month or part) | B12: 0.05 | C12: VAT Law Art. 43 – verify current rule
A13: Incorrect Return Penalty (% of difference) | B13: 0.5 | C13: VAT Law Art. 42 – indicative, verify current rule
A14: Periods in Year (calc) | B14: =IF(B8="Monthly",12,4)
A15: Months per Period (calc) | B15: =12/B14
A17: Tax Periods (auto-generated from the settings above)
A18: Period # | B18: Period Label | C18: Start Date | D18: End Date | E18: Return & Payment Due Date
A19: 1 | B19: =IF(C19="","",IF($B$8="Monthly",TEXT(C19,"mmm yyyy"),"Q"&A19&" "&TEXT(C19,"yyyy"))) | C19: =IF(A19>$B$14,"",EDATE($B$7,(A19-1)*$B$15)) | D19: =IF(C19="","",EDATE(C19,$B$15)-1) | E19: =IF(D19="","",EOMONTH(D19,1))
A20: 2 | B20: =IF(C20="","",IF($B$8="Monthly",TEXT(C20,"mmm yyyy"),"Q"&A20&" "&TEXT(C20,"yyyy"))) | C20: =IF(A20>$B$14,"",EDATE($B$7,(A20-1)*$B$15)) | D20: =IF(C20="","",EDATE(C20,$B$15)-1) | E20: =IF(D20="","",EOMONTH(D20,1))
A21: 3 | B21: =IF(C21="","",IF($B$8="Monthly",TEXT(C21,"mmm yyyy"),"Q"&A21&" "&TEXT(C21,"yyyy"))) | C21: =IF(A21>$B$14,"",EDATE($B$7,(A21-1)*$B$15)) | D21: =IF(C21="","",EDATE(C21,$B$15)-1) | E21: =IF(D21="","",EOMONTH(D21,1))
A22: 4 | B22: =IF(C22="","",IF($B$8="Monthly",TEXT(C22,"mmm yyyy"),"Q"&A22&" "&TEXT(C22,"yyyy"))) | C22: =IF(A22>$B$14,"",EDATE($B$7,(A22-1)*$B$15)) | D22: =IF(C22="","",EDATE(C22,$B$15)-1) | E22: =IF(D22="","",EOMONTH(D22,1))
A23: 5 | B23: =IF(C23="","",IF($B$8="Monthly",TEXT(C23,"mmm yyyy"),"Q"&A23&" "&TEXT(C23,"yyyy"))) | C23: =IF(A23>$B$14,"",EDATE($B$7,(A23-1)*$B$15)) | D23: =IF(C23="","",EDATE(C23,$B$15)-1) | E23: =IF(D23="","",EOMONTH(D23,1))
A24: 6 | B24: =IF(C24="","",IF($B$8="Monthly",TEXT(C24,"mmm yyyy"),"Q"&A24&" "&TEXT(C24,"yyyy"))) | C24: =IF(A24>$B$14,"",EDATE($B$7,(A24-1)*$B$15)) | D24: =IF(C24="","",EDATE(C24,$B$15)-1) | E24: =IF(D24="","",EOMONTH(D24,1))
A25: 7 | B25: =IF(C25="","",IF($B$8="Monthly",TEXT(C25,"mmm yyyy"),"Q"&A25&" "&TEXT(C25,"yyyy"))) | C25: =IF(A25>$B$14,"",EDATE($B$7,(A25-1)*$B$15)) | D25: =IF(C25="","",EDATE(C25,$B$15)-1) | E25: =IF(D25="","",EOMONTH(D25,1))
A26: 8 | B26: =IF(C26="","",IF($B$8="Monthly",TEXT(C26,"mmm yyyy"),"Q"&A26&" "&TEXT(C26,"yyyy"))) | C26: =IF(A26>$B$14,"",EDATE($B$7,(A26-1)*$B$15)) | D26: =IF(C26="","",EDATE(C26,$B$15)-1) | E26: =IF(D26="","",EOMONTH(D26,1))
A27: 9 | B27: =IF(C27="","",IF($B$8="Monthly",TEXT(C27,"mmm yyyy"),"Q"&A27&" "&TEXT(C27,"yyyy"))) | C27: =IF(A27>$B$14,"",EDATE($B$7,(A27-1)*$B$15)) | D27: =IF(C27="","",EDATE(C27,$B$15)-1) | E27: =IF(D27="","",EOMONTH(D27,1))
A28: 10 | B28: =IF(C28="","",IF($B$8="Monthly",TEXT(C28,"mmm yyyy"),"Q"&A28&" "&TEXT(C28,"yyyy"))) | C28: =IF(A28>$B$14,"",EDATE($B$7,(A28-1)*$B$15)) | D28: =IF(C28="","",EDATE(C28,$B$15)-1) | E28: =IF(D28="","",EOMONTH(D28,1))
A29: 11 | B29: =IF(C29="","",IF($B$8="Monthly",TEXT(C29,"mmm yyyy"),"Q"&A29&" "&TEXT(C29,"yyyy"))) | C29: =IF(A29>$B$14,"",EDATE($B$7,(A29-1)*$B$15)) | D29: =IF(C29="","",EDATE(C29,$B$15)-1) | E29: =IF(D29="","",EOMONTH(D29,1))
A30: 12 | B30: =IF(C30="","",IF($B$8="Monthly",TEXT(C30,"mmm yyyy"),"Q"&A30&" "&TEXT(C30,"yyyy"))) | C30: =IF(A30>$B$14,"",EDATE($B$7,(A30-1)*$B$15)) | D30: =IF(C30="","",EDATE(C30,$B$15)-1) | E30: =IF(D30="","",EOMONTH(D30,1))

Sheet Checklist
A1: Document Request Checklist (قائمة المستندات المطلوبة)
A2: Typical documents ZATCA requests in a VAT inspection. Track status, owner and file reference for each.
E3: Readiness: | F3: =(COUNTIF(G5:G42,"Ready")+COUNTIF(G5:G42,"Submitted")+COUNTIF(G5:G42,"N/A"))/COUNTA(G5:G42)
A4: # | B4: Area | C4: Document / Analysis Requested | D4: Prepared in this workbook? | E4: Owner | F4: Due Date | G4: Status | H4: File Ref / Location | I4: Notes
A5: 1 | B5: General | C5: VAT registration certificate, Commercial Registration, Articles of Association | G5: Not started
A6: 2 | B6: General | C6: Description of business activities and revenue streams + VAT treatment memo for each | G6: Not started
A7: 3 | B7: General | C7: List of branches, related parties and VAT group members (if any) | G7: Not started
A8: 4 | B8: General | C8: Chart of accounts with VAT mapping | D8: TB_Monthly col D | G8: Not started
A9: 5 | B9: General | C9: ERP / accounting system description and e-invoicing (FATOORA) solution details, onboarding & CSID | G9: Not started
A10: 6 | B10: General | C10: Authorisation letter for the representative dealing with ZATCA | G10: Not started
A11: 7 | B11: Financial | C11: Audited financial statements for each year under review | G11: Not started
A12: 8 | B12: Financial | C12: Monthly trial balances (opening, movements, closing) | D12: TB_Monthly | G12: Not started
A13: 9 | B13: Financial | C13: General ledger detail: revenue, VAT, and major expense accounts | G13: Not started
A14: 10 | B14: Financial | C14: Bank statements (ZATCA compares receipts with declared sales) | G14: Not started
A15: 11 | B15: VAT Returns | C15: Copies of all filed VAT returns and SADAD payment receipts | D15: VAT_Returns, ZATCA_Payments | G15: Not started
A16: 12 | B16: VAT Returns | C16: Voluntary disclosures / corrections filed (Box 14 usage) | D16: VAT_Returns col AJ | G16: Not started
A17: 13 | B17: Reconciliation | C17: Revenue per financial statements vs total sales per VAT returns | D17: Recon_Sales (bottom) | G17: Not started
A18: 14 | B18: Reconciliation | C18: Sales per VAT box vs sales listing vs GL – by period | D18: Recon_Sales | G18: Not started
A19: 15 | B19: Reconciliation | C19: Output VAT per GL vs returns | D19: Recon_OutputVAT | G19: Not started
A20: 16 | B20: Reconciliation | C20: Input VAT per GL vs returns | D20: Recon_InputVAT | G20: Not started
A21: 17 | B21: Reconciliation | C21: VAT control (payable) account roll-forward | D21: Recon_VAT_Account | G21: Not started
A22: 18 | B22: Reconciliation | C22: Customs imports (Bayan data) vs Box 8 | D22: Recon_InputVAT cols L–N | G22: Not started
A23: 19 | B23: Sales | C23: Sales listing (invoice level) with customer VAT numbers | D23: Sales_Register | G23: Not started
A24: 20 | B24: Sales | C24: Sample tax invoices, simplified invoices, credit/debit notes (XML / QR code) | G24: Not started
A25: 21 | B25: Sales | C25: Export evidence: customs exit declarations, bills of lading, contracts, proof of payment | D25: Sales_Register col N | G25: Not started
A26: 22 | B26: Sales | C26: Zero-rated domestic supply evidence (e.g. qualifying medicines, intl. transport) | D26: Sales_Register col N | G26: Not started
A27: 23 | B27: Sales | C27: Exempt supplies support (financial services margin, residential leases) | G27: Not started
A28: 24 | B28: Sales | C28: Major customer contracts incl. government contracts and VAT clauses | G28: Not started
A29: 25 | B29: Sales | C29: Deemed supplies: free samples, gifts, own use, staff benefits, write-offs | G29: Not started
A30: 26 | B30: Sales | C30: Related-party / intercompany charges and their VAT treatment | G30: Not started
A31: 27 | B31: Sales | C31: Fixed asset & real estate disposals (VAT / RETT treatment) | G31: Not started
A32: 28 | B32: Purchases | C32: Purchase listing (invoice level) with supplier VAT numbers | D32: Purchase_Register | G32: Not started
A33: 29 | B33: Purchases | C33: Sample supplier tax invoices supporting input VAT claimed | D33: Purchase_Register col K | G33: Not started
A34: 30 | B34: Purchases | C34: Import customs declarations (Bayan) and customs VAT payment proof | D34: Purchase_Register col M | G34: Not started
A35: 31 | B35: Purchases | C35: Reverse charge: foreign supplier invoices, contracts, RCM calculation | D35: Purchase_Register (Box 9) | G35: Not started
A36: 32 | B36: Purchases | C36: Blocked input VAT analysis (entertainment, vehicles, staff benefits) | D36: Purchase_Register col G | G36: Not started
A37: 33 | B37: Purchases | C37: Fixed asset register and capital assets adjustment | G37: Not started
A38: 34 | B38: Purchases | C38: Input VAT apportionment calculation (if exempt supplies exist) | G38: Not started
A39: 35 | B39: Cross-tax | C39: Withholding tax returns (foreign payments should match RCM in Box 9) | G39: Not started
A40: 36 | B40: Cross-tax | C40: Zakat / income tax return revenue vs VAT revenue | G40: Not started
...

Sheet TB_Monthly
A1: Monthly Trial Balance (ميزان المراجعة الشهري)
A2: Paste your TB: opening balance + monthly NET movements. Debit = positive, Credit = negative. Map every account in column D.
D3: Balance check (must = 0) → | E3: =ROUND(SUM(E6:E505),2) | F3: =ROUND(SUM(F6:F505),2) | G3: =ROUND(SUM(G6:G505),2) | H3: =ROUND(SUM(H6:H505),2) | I3: =ROUND(SUM(I6:I505),2) | J3: =ROUND(SUM(J6:J505),2) | K3: =ROUND(SUM(K6:K505),2) | L3: =ROUND(SUM(L6:L505),2) | ... S3: =ROUND(SUM(S6:S505),2)
E4: Month-end → | F4: =EOMONTH(Setup!$B$7,0) | G4: =EOMONTH(F4,1) | H4: =EOMONTH(G4,1) | I4: =EOMONTH(H4,1) | J4: =EOMONTH(I4,1) | K4: =EOMONTH(J4,1) | L4: =EOMONTH(K4,1) | M4: =EOMONTH(L4,1) | N4: =EOMONTH(M4,1) | ... Q4: =EOMONTH(P4,1)
A5: Account Code | B5: Account Name | C5: FS Class | D5: VAT Mapping | E5: Opening Balance | F5: Movement M1 | G5: Movement M2 | H5: Movement M3 | I5: Movement M4 | J5: Movement M5 | K5: Movement M6 | L5: Movement M7 | M5: Movement M8 | N5: Movement M9 | O5: Movement M10 | P5: Movement M11 | Q5: Movement M12 | R5: Total Movements | S5: Closing Balance
A6: 1100 | B6: Cash at Bank | C6: Asset | D6: Not VAT relevant | E6: 500000 | F6: 81000 | G6: -9000 | R6: =IF(A6="","",SUM(F6:Q6)) | S6: =IF(A6="","",E6+R6)
A7: 2210 | B7: Output VAT | C7: Liability | D7: Output VAT | E7: 0 | F7: -16500 | R7: =IF(A7="","",SUM(F7:Q7)) | S7: =IF(A7="","",E7+R7)
A8: 2220 | B8: Input VAT | C8: Asset | D8: Input VAT | E8: 0 | F8: 7500 | R8: =IF(A8="","",SUM(F8:Q8)) | S8: =IF(A8="","",E8+R8)
A9: 2230 | B9: VAT Payable - Settlement with ZATCA | C9: Liability | D9: VAT Payable / Settlement | E9: 0 | G9: 9000 | R9: =IF(A9="","",SUM(F9:Q9)) | S9: =IF(A9="","",E9+R9)
A10: 3100 | B10: Share Capital / Retained Earnings | C10: Equity | D10: Not VAT relevant | E10: -500000 | R10: =IF(A10="","",SUM(F10:Q10)) | S10: =IF(A10="","",E10+R10)
A11: 4100 | B11: Sales - Local | C11: Revenue | D11: Standard 15% (Box 1) | E11: 0 | F11: -100000 | R11: =IF(A11="","",SUM(F11:Q11)) | S11: =IF(A11="","",E11+R11)
A12: 4200 | B12: Sales - Export | C12: Revenue | D12: Export (Box 4) | E12: 0 | F12: -20000 | R12: =IF(A12="","",SUM(F12:Q12)) | S12: =IF(A12="","",E12+R12)
A13: 4900 | B13: Other Income - Dividends | C13: Revenue | D13: Revenue - Out of scope / Other income | E13: 0 | F13: -2000 | R13: =IF(A13="","",SUM(F13:Q13)) | S13: =IF(A13="","",E13+R13)
A14: 5100 | B14: Cost of Goods Purchased | C14: Expense | D14: Not VAT relevant | E14: 0 | F14: 40000 | R14: =IF(A14="","",SUM(F14:Q14)) | S14: =IF(A14="","",E14+R14)
A15: 6100 | B15: Consulting Fees - Foreign | C15: Expense | D15: Not VAT relevant | E15: 0 | F15: 10000 | R15: =IF(A15="","",SUM(F15:Q15)) | S15: =IF(A15="","",E15+R15)
R16: =IF(A16="","",SUM(F16:Q16)) | S16: =IF(A16="","",E16+R16)
R17: =IF(A17="","",SUM(F17:Q17)) | S17: =IF(A17="","",E17+R17)
R18: =IF(A18="","",SUM(F18:Q18)) | S18: =IF(A18="","",E18+R18)
R19: =IF(A19="","",SUM(F19:Q19)) | S19: =IF(A19="","",E19+R19)
R20: =IF(A20="","",SUM(F20:Q20)) | S20: =IF(A20="","",E20+R20)
R21: =IF(A21="","",SUM(F21:Q21)) | S21: =IF(A21="","",E21+R21)
R22: =IF(A22="","",SUM(F22:Q22)) | S22: =IF(A22="","",E22+R22)
R23: =IF(A23="","",SUM(F23:Q23)) | S23: =IF(A23="","",E23+R23)
R24: =IF(A24="","",SUM(F24:Q24)) | S24: =IF(A24="","",E24+R24)
R25: =IF(A25="","",SUM(F25:Q25)) | S25: =IF(A25="","",E25+R25)
R26: =IF(A26="","",SUM(F26:Q26)) | S26: =IF(A26="","",E26+R26)
R27: =IF(A27="","",SUM(F27:Q27)) | S27: =IF(A27="","",E27+R27)
... R505: =IF(A505="","",SUM(F505:Q505)) | S505: =IF(A505="","",E505+R505)

Sheet VAT_Returns
A1: VAT Returns as Filed (إقرارات ضريبة القيمة المضافة)
A2: Copy each return EXACTLY as filed on the ZATCA portal. Adjustments (credit notes) as negative. Grey columns recalculate the return and check it.
F4: Box 1 – Standard rated sales 15% المبيعات الخاضعة للنسبة الأساسية | I4: Box 2 – Sales to citizens (private health / education) المبيعات للمواطنين | L4: Box 3 – Zero-rated domestic sales المبيعات المحلية بنسبة صفر | O4: Box 4 – Exports الصادرات | R4: Box 5 – Exempt sales المبيعات المعفاة | U4: Box 7 – Standard rated domestic purchases 15% المشتريات المحلية الخاضعة للنسبة الأساسية | X4: Box 8 – Imports – VAT paid at customs الاستيرادات – ضريبة مدفوعة في الجمارك | AA4: Box 9 – Imports – reverse charge (RCM) الاستيرادات – الاحتساب العكسي | AD4: Box 10 – Zero-rated purchases المشتريات بنسبة صفر | AG4: Box 11 – Exempt purchases المشتريات المعفاة | AJ4: Box 14 – Corrections from previous periods (±5,000) | AK4: Box 15 – VAT credit carried forward | AL4: Box 16 – Net VAT due AS FILED | AM4: Box 6 – Total sales (net, recalc) | AN4: Box 6 – Output VAT incl. RCM (recalc) | AO4: Box 12 – Total purchases (net, recalc) | AP4: Box 12 – Input VAT (recalc) | AQ4: Box 13 – Net VAT for period (recalc) | AR4: Box 16 – Net VAT due (recalc) | AS4: Arithmetic check (filed vs recalc) | AT4: Filed on time? | AU4: Box 14 within ±5,000?
F5: Amount | G5: Adjustment | H5: VAT | I5: Amount | J5: Adjustment | K5: VAT | L5: Amount | M5: Adjustment | N5: VAT | O5: Amount | P5: Adjustment | Q5: VAT | R5: Amount | S5: Adjustment | T5: VAT | U5: Amount | V5: Adjustment | W5: VAT | X5: Amount | Y5: Adjustment | Z5: VAT | AA5: Amount | AB5: Adjustment | AC5: VAT | AD5: Amount | AE5: Adjustment | AF5: VAT | AG5: Amount | AH5: Adjustment | AI5: VAT
A6: =IF(Setup!C19="","",Setup!A19) | B6: =Setup!B19 | C6: =Setup!E19 | D6: 45713 | E6: VAT-2025-01 | F6: 100000 | H6: 15000 | O6: 20000 | U6: 40000 | W6: 6000 | AA6: 10000 | AC6: 1500 | AJ6: 0 | AK6: 0 | AL6: 9000 | AM6: =IF($A6="","",(F6+G6)+(I6+J6)+(L6+M6)+(O6+P6)+(R6+S6)) | AN6: =IF($A6="","",H6+K6+N6+Q6+T6+AC6) | AO6: =IF($A6="","",(U6+V6)+(X6+Y6)+(AA6+AB6)+(AD6+AE6)+(AG6+AH6)) | AP6: =IF($A6="","",W6+Z6+AC6+AF6+AI6) | AQ6: =IF($A6="","",AN6-AP6) | AR6: =IF($A6="","",AQ6+AJ6-AK6) | AS6: =IF($A6="","",IF(AND(D6="",AL6=""),"– Not entered",IF(ABS(AL6-AR6)<=Setup!$B$10,"✓ Agrees","✗ Filed ≠ recalc"))) | AT6: =IF($A6="","",IF(D6="","– No filing date",IF(D6<=C6,"✓ On time","✗ Late "&(D6-C6)&" days"))) | AU6: =IF($A6="","",IF(ABS(AJ6)<=5000,"✓ OK","✗ >5,000 – needs voluntary disclosure"))
A7: =IF(Setup!C20="","",Setup!A20) | B7: =Setup!B20 | C7: =Setup!E20 | AM7: =IF($A7="","",(F7+G7)+(I7+J7)+(L7+M7)+(O7+P7)+(R7+S7)) | AN7: =IF($A7="","",H7+K7+N7+Q7+T7+AC7) | AO7: =IF($A7="","",(U7+V7)+(X7+Y7)+(AA7+AB7)+(AD7+AE7)+(AG7+AH7)) | AP7: =IF($A7="","",W7+Z7+AC7+AF7+AI7) | AQ7: =IF($A7="","",AN7-AP7) | AR7: =IF($A7="","",AQ7+AJ7-AK7) | AS7: =IF($A7="","",IF(AND(D7="",AL7=""),"– Not entered",IF(ABS(AL7-AR7)<=Setup!$B$10,"✓ Agrees","✗ Filed ≠ recalc"))) | AT7: =IF($A7="","",IF(D7="","– No filing date",IF(D7<=C7,"✓ On time","✗ Late "&(D7-C7)&" days"))) | AU7: =IF($A7="","",IF(ABS(AJ7)<=5000,"✓ OK","✗ >5,000 – needs voluntary disclosure"))
A8: =IF(Setup!C21="","",Setup!A21) | B8: =Setup!B21 | C8: =Setup!E21 | AM8: =IF($A8="","",(F8+G8)+(I8+J8)+(L8+M8)+(O8+P8)+(R8+S8)) | AN8: =IF($A8="","",H8+K8+N8+Q8+T8+AC8) | AO8: =IF($A8="","",(U8+V8)+(X8+Y8)+(AA8+AB8)+(AD8+AE8)+(AG8+AH8)) | AP8: =IF($A8="","",W8+Z8+AC8+AF8+AI8) | AQ8: =IF($A8="","",AN8-AP8) | AR8: =IF($A8="","",AQ8+AJ8-AK8) | AS8: =IF($A8="","",IF(AND(D8="",AL8=""),"– Not entered",IF(ABS(AL8-AR8)<=Setup!$B$10,"✓ Agrees","✗ Filed ≠ recalc"))) | AT8: =IF($A8="","",IF(D8="","– No filing date",IF(D8<=C8,"✓ On time","✗ Late "&(D8-C8)&" days"))) | AU8: =IF($A8="","",IF(ABS(AJ8)<=5000,"✓ OK","✗ >5,000 – needs voluntary disclosure"))
A9: =IF(Setup!C22="","",Setup!A22) | B9: =Setup!B22 | C9: =Setup!E22 | AM9: =IF($A9="","",(F9+G9)+(I9+J9)+(L9+M9)+(O9+P9)+(R9+S9)) | AN9: =IF($A9="","",H9+K9+N9+Q9+T9+AC9) | AO9: =IF($A9="","",(U9+V9)+(X9+Y9)+(AA9+AB9)+(AD9+AE9)+(AG9+AH9)) | AP9: =IF($A9="","",W9+Z9+AC9+AF9+AI9) | AQ9: =IF($A9="","",AN9-AP9) | AR9: =IF($A9="","",AQ9+AJ9-AK9) | AS9: =IF($A9="","",IF(AND(D9="",AL9=""),"– Not entered",IF(ABS(AL9-AR9)<=Setup!$B$10,"✓ Agrees","✗ Filed ≠ recalc"))) | AT9: =IF($A9="","",IF(D9="","– No filing date",IF(D9<=C9,"✓ On time","✗ Late "&(D9-C9)&" days"))) | AU9: =IF($A9="","",IF(ABS(AJ9)<=5000,"✓ OK","✗ >5,000 – needs voluntary disclosure"))
A10: =IF(Setup!C23="","",Setup!A23) | B10: =Setup!B23 | C10: =Setup!E23 | AM10: =IF($A10="","",(F10+G10)+(I10+J10)+(L10+M10)+(O10+P10)+(R10+S10)) | AN10: =IF($A10="","",H10+K10+N10+Q10+T10+AC10) | AO10: =IF($A10="","",(U10+V10)+(X10+Y10)+(AA10+AB10)+(AD10+AE10)+(AG10+AH10)) | AP10: =IF($A10="","",W10+Z10+AC10+AF10+AI10) | AQ10: =IF($A10="","",AN10-AP10) | AR10: =IF($A10="","",AQ10+AJ10-AK10) | AS10: =IF($A10="","",IF(AND(D10="",AL10=""),"– Not entered",IF(ABS(AL10-AR10)<=Setup!$B$10,"✓ Agrees","✗ Filed ≠ recalc"))) | AT10: =IF($A10="","",IF(D10="","– No filing date",IF(D10<=C10,"✓ On time","✗ Late "&(D10-C10)&" days"))) | AU10: =IF($A10="","",IF(ABS(AJ10)<=5000,"✓ OK","✗ >5,000 – needs voluntary disclosure"))
A11: =IF(Setup!C24="","",Setup!A24) | B11: =Setup!B24 | C11: =Setup!E24 | AM11: =IF($A11="","",(F11+G11)+(I11+J11)+(L11+M11)+(O11+P11)+(R11+S11)) | AN11: =IF($A11="","",H11+K11+N11+Q11+T11+AC11) | AO11: =IF($A11="","",(U11+V11)+(X11+Y11)+(AA11+AB11)+(AD11+AE11)+(AG11+AH11)) | AP11: =IF($A11="","",W11+Z11+AC11+AF11+AI11) | AQ11: =IF($A11="","",AN11-AP11) | AR11: =IF($A11="","",AQ11+AJ11-AK11) | AS11: =IF($A11="","",IF(AND(D11="",AL11=""),"– Not entered",IF(ABS(AL11-AR11)<=Setup!$B$10,"✓ Agrees","✗ Filed ≠ recalc"))) | AT11: =IF($A11="","",IF(D11="","– No filing date",IF(D11<=C11,"✓ On time","✗ Late "&(D11-C11)&" days"))) | AU11: =IF($A11="","",IF(ABS(AJ11)<=5000,"✓ OK","✗ >5,000 – needs voluntary disclosure"))
A12: =IF(Setup!C25="","",Setup!A25) | B12: =Setup!B25 | C12: =Setup!E25 | AM12: =IF($A12="","",(F12+G12)+(I12+J12)+(L12+M12)+(O12+P12)+(R12+S12)) | AN12: =IF($A12="","",H12+K12+N12+Q12+T12+AC12) | AO12: =IF($A12="","",(U12+V12)+(X12+Y12)+(AA12+AB12)+(AD12+AE12)+(AG12+AH12)) | AP12: =IF($A12="","",W12+Z12+AC12+AF12+AI12) | AQ12: =IF($A12="","",AN12-AP12) | AR12: =IF($A12="","",AQ12+AJ12-AK12) | AS12: =IF($A12="","",IF(AND(D12="",AL12=""),"– Not entered",IF(ABS(AL12-AR12)<=Setup!$B$10,"✓ Agrees","✗ Filed ≠ recalc"))) | AT12: =IF($A12="","",IF(D12="","– No filing date",IF(D12<=C12,"✓ On time","✗ Late "&(D12-C12)&" days"))) | AU12: =IF($A12="","",IF(ABS(AJ12)<=5000,"✓ OK","✗ >5,000 – needs voluntary disclosure"))
A13: =IF(Setup!C26="","",Setup!A26) | B13: =Setup!B26 | C13: =Setup!E26 | AM13: =IF($A13="","",(F13+G13)+(I13+J13)+(L13+M13)+(O13+P13)+(R13+S13)) | AN13: =IF($A13="","",H13+K13+N13+Q13+T13+AC13) | AO13: =IF($A13="","",(U13+V13)+(X13+Y13)+(AA13+AB13)+(AD13+AE13)+(AG13+AH13)) | AP13: =IF($A13="","",W13+Z13+AC13+AF13+AI13) | AQ13: =IF($A13="","",AN13-AP13) | AR13: =IF($A13="","",AQ13+AJ13-AK13) | AS13: =IF($A13="","",IF(AND(D13="",AL13=""),"– Not entered",IF(ABS(AL13-AR13)<=Setup!$B$10,"✓ Agrees","✗ Filed ≠ recalc"))) | AT13: =IF($A13="","",IF(D13="","– No filing date",IF(D13<=C13,"✓ On time","✗ Late "&(D13-C13)&" days"))) | AU13: =IF($A13="","",IF(ABS(AJ13)<=5000,"✓ OK","✗ >5,000 – needs voluntary disclosure"))
A14: =IF(Setup!C27="","",Setup!A27) | B14: =Setup!B27 | C14: =Setup!E27 | AM14: =IF($A14="","",(F14+G14)+(I14+J14)+(L14+M14)+(O14+P14)+(R14+S14)) | AN14: =IF($A14="","",H14+K14+N14+Q14+T14+AC14) | AO14: =IF($A14="","",(U14+V14)+(X14+Y14)+(AA14+AB14)+(AD14+AE14)+(AG14+AH14)) | AP14: =IF($A14="","",W14+Z14+AC14+AF14+AI14) | AQ14: =IF($A14="","",AN14-AP14) | AR14: =IF($A14="","",AQ14+AJ14-AK14) | AS14: =IF($A14="","",IF(AND(D14="",AL14=""),"– Not entered",IF(ABS(AL14-AR14)<=Setup!$B$10,"✓ Agrees","✗ Filed ≠ recalc"))) | AT14: =IF($A14="","",IF(D14="","– No filing date",IF(D14<=C14,"✓ On time","✗ Late "&(D14-C14)&" days"))) | AU14: =IF($A14="","",IF(ABS(AJ14)<=5000,"✓ OK","✗ >5,000 – needs voluntary disclosure"))
A15: =IF(Setup!C28="","",Setup!A28) | B15: =Setup!B28 | C15: =Setup!E28 | AM15: =IF($A15="","",(F15+G15)+(I15+J15)+(L15+M15)+(O15+P15)+(R15+S15)) | AN15: =IF($A15="","",H15+K15+N15+Q15+T15+AC15) | AO15: =IF($A15="","",(U15+V15)+(X15+Y15)+(AA15+AB15)+(AD15+AE15)+(AG15+AH15)) | AP15: =IF($A15="","",W15+Z15+AC15+AF15+AI15) | AQ15: =IF($A15="","",AN15-AP15) | AR15: =IF($A15="","",AQ15+AJ15-AK15) | AS15: =IF($A15="","",IF(AND(D15="",AL15=""),"– Not entered",IF(ABS(AL15-AR15)<=Setup!$B$10,"✓ Agrees","✗ Filed ≠ recalc"))) | AT15: =IF($A15="","",IF(D15="","– No filing date",IF(D15<=C15,"✓ On time","✗ Late "&(D15-C15)&" days"))) | AU15: =IF($A15="","",IF(ABS(AJ15)<=5000,"✓ OK","✗ >5,000 – needs voluntary disclosure"))
A16: =IF(Setup!C29="","",Setup!A29) | B16: =Setup!B29 | C16: =Setup!E29 | AM16: =IF($A16="","",(F16+G16)+(I16+J16)+(L16+M16)+(O16+P16)+(R16+S16)) | AN16: =IF($A16="","",H16+K16+N16+Q16+T16+AC16) | AO16: =IF($A16="","",(U16+V16)+(X16+Y16)+(AA16+AB16)+(AD16+AE16)+(AG16+AH16)) | AP16: =IF($A16="","",W16+Z16+AC16+AF16+AI16) | AQ16: =IF($A16="","",AN16-AP16) | AR16: =IF($A16="","",AQ16+AJ16-AK16) | AS16: =IF($A16="","",IF(AND(D16="",AL16=""),"– Not entered",IF(ABS(AL16-AR16)<=Setup!$B$10,"✓ Agrees","✗ Filed ≠ recalc"))) | AT16: =IF($A16="","",IF(D16="","– No filing date",IF(D16<=C16,"✓ On time","✗ Late "&(D16-C16)&" days"))) | AU16: =IF($A16="","",IF(ABS(AJ16)<=5000,"✓ OK","✗ >5,000 – needs voluntary disclosure"))
A17: =IF(Setup!C30="","",Setup!A30) | B17: =Setup!B30 | C17: =Setup!E30 | AM17: =IF($A17="","",(F17+G17)+(I17+J17)+(L17+M17)+(O17+P17)+(R17+S17)) | AN17: =IF($A17="","",H17+K17+N17+Q17+T17+AC17) | AO17: =IF($A17="","",(U17+V17)+(X17+Y17)+(AA17+AB17)+(AD17+AE17)+(AG17+AH17)) | AP17: =IF($A17="","",W17+Z17+AC17+AF17+AI17) | AQ17: =IF($A17="","",AN17-AP17) | AR17: =IF($A17="","",AQ17+AJ17-AK17) | AS17: =IF($A17="","",IF(AND(D17="",AL17=""),"– Not entered",IF(ABS(AL17-AR17)<=Setup!$B$10,"✓ Agrees","✗ Filed ≠ recalc"))) | AT17: =IF($A17="","",IF(D17="","– No filing date",IF(D17<=C17,"✓ On time","✗ Late "&(D17-C17)&" days"))) | AU17: =IF($A17="","",IF(ABS(AJ17)<=5000,"✓ OK","✗ >5,000 – needs voluntary disclosure"))
B18: TOTAL YEAR | F18: =SUM(F6:F17) | G18: =SUM(G6:G17) | H18: =SUM(H6:H17) | I18: =SUM(I6:I17) | J18: =SUM(J6:J17) | K18: =SUM(K6:K17) | L18: =SUM(L6:L17) | M18: =SUM(M6:M17) | ... AR18: =SUM(AR6:AR17)
A20: Example: January 2025 is filled in to show the format – overwrite with your real filed figures.

Sheet Sales_Register
A1: Sales Register – invoice level (سجل المبيعات)
A2: Export from ERP / FATOORA. Credit notes as NEGATIVE amounts. Grey columns calculate expected VAT and flag issues ZATCA will look for.
A3: Rows flagged: | B3: =SUMPRODUCT((A6:A5005<>"")*(LEN(R6:R5005)>0)) | C3: Rows with data: | D3: =COUNT(A6:A5005)
A5: Invoice Date | B5: Invoice No | C5: Document Type | D5: Customer Name | E5: Customer VAT No | F5: Customer Type | G5: VAT Category | H5: Net Amount (SAR) | I5: VAT Amount (SAR) | J5: Total (SAR) | K5: E-Invoice UUID / Ref | L5: Reported/Cleared on FATOORA? | M5: GL Revenue Account | N5: Evidence Ref (export / zero-rate) | O5: Period # | P5: Expected VAT | Q5: VAT Difference | R5: Exceptions / Flags
A6: 45672 | B6: INV-0001 | C6: Tax Invoice | D6: ABC Trading Co | E6: 310123456700003 | F6: B2B - VAT registered | G6: Standard 15% (Box 1) | H6: 100000 | I6: 15000 | J6: =IF(A6="","",H6+I6) | K6: e3b0c442-98fc-1c14 | L6: Yes | M6: 4100 | O6: =IF(A6="","",SUMPRODUCT((A6>=Setup!$C$19:$C$30)*(A6<=Setup!$D$19:$D$30)*Setup!$A$19:$A$30)) | P6: =IF(A6="","",IF(G6="Standard 15% (Box 1)",ROUND(H6*Setup!$B$9,2),0)) | Q6: =IF(A6="","",I6-P6) | R6: =IF(A6="","",IF(O6=0,"Outside audit periods; ","")&IF(G6="","No VAT category; ","")&IF(ABS(Q6)>Setup!$B$10,"VAT ≠ 15% × net; ","")&IF(AND(F6="B2B - VAT registered",NOT(AND(LEN(E6)=15,LEFT(E6,1)="3",RIGHT(E6,1)="3",ISNUMBER(--E6)))),"Invalid/missing customer VAT no; ","")&IF(L6<>"Yes","Not reported/cleared on FATOORA; ","")&IF(AND(OR(G6="Zero-rated domestic (Box 3)",G6="Export (Box 4)"),N6=""),"Zero-rate/export evidence missing; ","")&IF(AND(C6="Credit Note",H6>0),"Credit note should be negative; ","")&IF(AND(C6="Simplified Tax Invoice",F6="B2B - VAT registered"),"Simplified invoice issued to VAT-registered B2B; ",""))
A7: 45677 | B7: INV-0002 | C7: Tax Invoice | D7: Gulf Imports LLC (UAE) | F7: B2B - Not registered | G7: Export (Box 4) | H7: 20000 | I7: 0 | J7: =IF(A7="","",H7+I7) | K7: a1f2c3d4-55aa-77bb | L7: Yes | M7: 4200 | N7: Customs exit decl. 123456 + B/L GLF-889 | O7: =IF(A7="","",SUMPRODUCT((A7>=Setup!$C$19:$C$30)*(A7<=Setup!$D$19:$D$30)*Setup!$A$19:$A$30)) | P7: =IF(A7="","",IF(G7="Standard 15% (Box 1)",ROUND(H7*Setup!$B$9,2),0)) | Q7: =IF(A7="","",I7-P7) | R7: =IF(A7="","",IF(O7=0,"Outside audit periods; ","")&IF(G7="","No VAT category; ","")&IF(ABS(Q7)>Setup!$B$10,"VAT ≠ 15% × net; ","")&IF(AND(F7="B2B - VAT registered",NOT(AND(LEN(E7)=15,LEFT(E7,1)="3",RIGHT(E7,1)="3",ISNUMBER(--E7)))),"Invalid/missing customer VAT no; ","")&IF(L7<>"Yes","Not reported/cleared on FATOORA; ","")&IF(AND(OR(G7="Zero-rated domestic (Box 3)",G7="Export (Box 4)"),N7=""),"Zero-rate/export evidence missing; ","")&IF(AND(C7="Credit Note",H7>0),"Credit note should be negative; ","")&IF(AND(C7="Simplified Tax Invoice",F7="B2B - VAT registered"),"Simplified invoice issued to VAT-registered B2B; ",""))
J8: =IF(A8="","",H8+I8) | O8: =IF(A8="","",SUMPRODUCT((A8>=Setup!$C$19:$C$30)*(A8<=Setup!$D$19:$D$30)*Setup!$A$19:$A$30)) | P8: =IF(A8="","",IF(G8="Standard 15% (Box 1)",ROUND(H8*Setup!$B$9,2),0)) | Q8: =IF(A8="","",I8-P8) | R8: =IF(A8="","",IF(O8=0,"Outside audit periods; ","")&IF(G8="","No VAT category; ","")&IF(ABS(Q8)>Setup!$B$10,"VAT ≠ 15% × net; ","")&IF(AND(F8="B2B - VAT registered",NOT(AND(LEN(E8)=15,LEFT(E8,1)="3",RIGHT(E8,1)="3",ISNUMBER(--E8)))),"Invalid/missing customer VAT no; ","")&IF(L8<>"Yes","Not reported/cleared on FATOORA; ","")&IF(AND(OR(G8="Zero-rated domestic (Box 3)",G8="Export (Box 4)"),N8=""),"Zero-rate/export evidence missing; ","")&IF(AND(C8="Credit Note",H8>0),"Credit note should be negative; ","")&IF(AND(C8="Simplified Tax Invoice",F8="B2B - VAT registered"),"Simplified invoice issued to VAT-registered B2B; ",""))
J9: =IF(A9="","",H9+I9) | O9: =IF(A9="","",SUMPRODUCT((A9>=Setup!$C$19:$C$30)*(A9<=Setup!$D$19:$D$30)*Setup!$A$19:$A$30)) | P9: =IF(A9="","",IF(G9="Standard 15% (Box 1)",ROUND(H9*Setup!$B$9,2),0)) | Q9: =IF(A9="","",I9-P9) | R9: =IF(A9="","",IF(O9=0,"Outside audit periods; ","")&IF(G9="","No VAT category; ","")&IF(ABS(Q9)>Setup!$B$10,"VAT ≠ 15% × net; ","")&IF(AND(F9="B2B - VAT registered",NOT(AND(LEN(E9)=15,LEFT(E9,1)="3",RIGHT(E9,1)="3",ISNUMBER(--E9)))),"Invalid/missing customer VAT no; ","")&IF(L9<>"Yes","Not reported/cleared on FATOORA; ","")&IF(AND(OR(G9="Zero-rated domestic (Box 3)",G9="Export (Box 4)"),N9=""),"Zero-rate/export evidence missing; ","")&IF(AND(C9="Credit Note",H9>0),"Credit note should be negative; ","")&IF(AND(C9="Simplified Tax Invoice",F9="B2B - VAT registered"),"Simplified invoice issued to VAT-registered B2B; ",""))
J10: =IF(A10="","",H10+I10) | O10: =IF(A10="","",SUMPRODUCT((A10>=Setup!$C$19:$C$30)*(A10<=Setup!$D$19:$D$30)*Setup!$A$19:$A$30)) | P10: =IF(A10="","",IF(G10="Standard 15% (Box 1)",ROUND(H10*Setup!$B$9,2),0)) | Q10: =IF(A10="","",I10-P10) | R10: =IF(A10="","",IF(O10=0,"Outside audit periods; ","")&IF(G10="","No VAT category; ","")&IF(ABS(Q10)>Setup!$B$10,"VAT ≠ 15% × net; ","")&IF(AND(F10="B2B - VAT registered",NOT(AND(LEN(E10)=15,LEFT(E10,1)="3",RIGHT(E10,1)="3",ISNUMBER(--E10)))),"Invalid/missing customer VAT no; ","")&IF(L10<>"Yes","Not reported/cleared on FATOORA; ","")&IF(AND(OR(G10="Zero-rated domestic (Box 3)",G10="Export (Box 4)"),N10=""),"Zero-rate/export evidence missing; ","")&IF(AND(C10="Credit Note",H10>0),"Credit note should be negative; ","")&IF(AND(C10="Simplified Tax Invoice",F10="B2B - VAT registered"),"Simplified invoice issued to VAT-registered B2B; ",""))
J11: =IF(A11="","",H11+I11) | O11: =IF(A11="","",SUMPRODUCT((A11>=Setup!$C$19:$C$30)*(A11<=Setup!$D$19:$D$30)*Setup!$A$19:$A$30)) | P11: =IF(A11="","",IF(G11="Standard 15% (Box 1)",ROUND(H11*Setup!$B$9,2),0)) | Q11: =IF(A11="","",I11-P11) | R11: =IF(A11="","",IF(O11=0,"Outside audit periods; ","")&IF(G11="","No VAT category; ","")&IF(ABS(Q11)>Setup!$B$10,"VAT ≠ 15% × net; ","")&IF(AND(F11="B2B - VAT registered",NOT(AND(LEN(E11)=15,LEFT(E11,1)="3",RIGHT(E11,1)="3",ISNUMBER(--E11)))),"Invalid/missing customer VAT no; ","")&IF(L11<>"Yes","Not reported/cleared on FATOORA; ","")&IF(AND(OR(G11="Zero-rated domestic (Box 3)",G11="Export (Box 4)"),N11=""),"Zero-rate/export evidence missing; ","")&IF(AND(C11="Credit Note",H11>0),"Credit note should be negative; ","")&IF(AND(C11="Simplified Tax Invoice",F11="B2B - VAT registered"),"Simplified invoice issued to VAT-registered B2B; ",""))
J12: =IF(A12="","",H12+I12) | O12: =IF(A12="","",SUMPRODUCT((A12>=Setup!$C$19:$C$30)*(A12<=Setup!$D$19:$D$30)*Setup!$A$19:$A$30)) | P12: =IF(A12="","",IF(G12="Standard 15% (Box 1)",ROUND(H12*Setup!$B$9,2),0)) | Q12: =IF(A12="","",I12-P12) | R12: =IF(A12="","",IF(O12=0,"Outside audit periods; ","")&IF(G12="","No VAT category; ","")&IF(ABS(Q12)>Setup!$B$10,"VAT ≠ 15% × net; ","")&IF(AND(F12="B2B - VAT registered",NOT(AND(LEN(E12)=15,LEFT(E12,1)="3",RIGHT(E12,1)="3",ISNUMBER(--E12)))),"Invalid/missing customer VAT no; ","")&IF(L12<>"Yes","Not reported/cleared on FATOORA; ","")&IF(AND(OR(G12="Zero-rated domestic (Box 3)",G12="Export (Box 4)"),N12=""),"Zero-rate/export evidence missing; ","")&IF(AND(C12="Credit Note",H12>0),"Credit note should be negative; ","")&IF(AND(C12="Simplified Tax Invoice",F12="B2B - VAT registered"),"Simplified invoice issued to VAT-registered B2B; ",""))
J13: =IF(A13="","",H13+I13) | O13: =IF(A13="","",SUMPRODUCT((A13>=Setup!$C$19:$C$30)*(A13<=Setup!$D$19:$D$30)*Setup!$A$19:$A$30)) | P13: =IF(A13="","",IF(G13="Standard 15% (Box 1)",ROUND(H13*Setup!$B$9,2),0)) | Q13: =IF(A13="","",I13-P13) | R13: =IF(A13="","",IF(O13=0,"Outside audit periods; ","")&IF(G13="","No VAT category; ","")&IF(ABS(Q13)>Setup!$B$10,"VAT ≠ 15% × net; ","")&IF(AND(F13="B2B - VAT registered",NOT(AND(LEN(E13)=15,LEFT(E13,1)="3",RIGHT(E13,1)="3",ISNUMBER(--E13)))),"Invalid/missing customer VAT no; ","")&IF(L13<>"Yes","Not reported/cleared on FATOORA; ","")&IF(AND(OR(G13="Zero-rated domestic (Box 3)",G13="Export (Box 4)"),N13=""),"Zero-rate/export evidence missing; ","")&IF(AND(C13="Credit Note",H13>0),"Credit note should be negative; ","")&IF(AND(C13="Simplified Tax Invoice",F13="B2B - VAT registered"),"Simplified invoice issued to VAT-registered B2B; ",""))
J14: =IF(A14="","",H14+I14) | O14: =IF(A14="","",SUMPRODUCT((A14>=Setup!$C$19:$C$30)*(A14<=Setup!$D$19:$D$30)*Setup!$A$19:$A$30)) | P14: =IF(A14="","",IF(G14="Standard 15% (Box 1)",ROUND(H14*Setup!$B$9,2),0)) | Q14: =IF(A14="","",I14-P14) | R14: =IF(A14="","",IF(O14=0,"Outside audit periods; ","")&IF(G14="","No VAT category; ","")&IF(ABS(Q14)>Setup!$B$10,"VAT ≠ 15% × net; ","")&IF(AND(F14="B2B - VAT registered",NOT(AND(LEN(E14)=15,LEFT(E14,1)="3",RIGHT(E14,1)="3",ISNUMBER(--E14)))),"Invalid/missing customer VAT no; ","")&IF(L14<>"Yes","Not reported/cleared on FATOORA; ","")&IF(AND(OR(G14="Zero-rated domestic (Box 3)",G14="Export (Box 4)"),N14=""),"Zero-rate/export evidence missing; ","")&IF(AND(C14="Credit Note",H14>0),"Credit note should be negative; ","")&IF(AND(C14="Simplified Tax Invoice",F14="B2B - VAT registered"),"Simplified invoice issued to VAT-registered B2B; ",""))
J15: =IF(A15="","",H15+I15) | O15: =IF(A15="","",SUMPRODUCT((A15>=Setup!$C$19:$C$30)*(A15<=Setup!$D$19:$D$30)*Setup!$A$19:$A$30)) | P15: =IF(A15="","",IF(G15="Standard 15% (Box 1)",ROUND(H15*Setup!$B$9,2),0)) | Q15: =IF(A15="","",I15-P15) | R15: =IF(A15="","",IF(O15=0,"Outside audit periods; ","")&IF(G15="","No VAT category; ","")&IF(ABS(Q15)>Setup!$B$10,"VAT ≠ 15% × net; ","")&IF(AND(F15="B2B - VAT registered",NOT(AND(LEN(E15)=15,LEFT(E15,1)="3",RIGHT(E15,1)="3",ISNUMBER(--E15)))),"Invalid/missing customer VAT no; ","")&IF(L15<>"Yes","Not reported/cleared on FATOORA; ","")&IF(AND(OR(G15="Zero-rated domestic (Box 3)",G15="Export (Box 4)"),N15=""),"Zero-rate/export evidence missing; ","")&IF(AND(C15="Credit Note",H15>0),"Credit note should be negative; ","")&IF(AND(C15="Simplified Tax Invoice",F15="B2B - VAT registered"),"Simplified invoice issued to VAT-registered B2B; ",""))
J16: =IF(A16="","",H16+I16) | O16: =IF(A16="","",SUMPRODUCT((A16>=Setup!$C$19:$C$30)*(A16<=Setup!$D$19:$D$30)*Setup!$A$19:$A$30)) | P16: =IF(A16="","",IF(G16="Standard 15% (Box 1)",ROUND(H16*Setup!$B$9,2),0)) | Q16: =IF(A16="","",I16-P16) | R16: =IF(A16="","",IF(O16=0,"Outside audit periods; ","")&IF(G16="","No VAT category; ","")&IF(ABS(Q16)>Setup!$B$10,"VAT ≠ 15% × net; ","")&IF(AND(F16="B2B - VAT registered",NOT(AND(LEN(E16)=15,LEFT(E16,1)="3",RIGHT(E16,1)="3",ISNUMBER(--E16)))),"Invalid/missing customer VAT no; ","")&IF(L16<>"Yes","Not reported/cleared on FATOORA; ","")&IF(AND(OR(G16="Zero-rated domestic (Box 3)",G16="Export (Box 4)"),N16=""),"Zero-rate/export evidence missing; ","")&IF(AND(C16="Credit Note",H16>0),"Credit note should be negative; ","")&IF(AND(C16="Simplified Tax Invoice",F16="B2B - VAT registered"),"Simplified invoice issued to VAT-registered B2B; ",""))
J17: =IF(A17="","",H17+I17) | O17: =IF(A17="","",SUMPRODUCT((A17>=Setup!$C$19:$C$30)*(A17<=Setup!$D$19:$D$30)*Setup!$A$19:$A$30)) | P17: =IF(A17="","",IF(G17="Standard 15% (Box 1)",ROUND(H17*Setup!$B$9,2),0)) | Q17: =IF(A17="","",I17-P17) | R17: =IF(A17="","",IF(O17=0,"Outside audit periods; ","")&IF(G17="","No VAT category; ","")&IF(ABS(Q17)>Setup!$B$10,"VAT ≠ 15% × net; ","")&IF(AND(F17="B2B - VAT registered",NOT(AND(LEN(E17)=15,LEFT(E17,1)="3",RIGHT(E17,1)="3",ISNUMBER(--E17)))),"Invalid/missing customer VAT no; ","")&IF(L17<>"Yes","Not reported/cleared on FATOORA; ","")&IF(AND(OR(G17="Zero-rated domestic (Box 3)",G17="Export (Box 4)"),N17=""),"Zero-rate/export evidence missing; ","")&IF(AND(C17="Credit Note",H17>0),"Credit note should be negative; ","")&IF(AND(C17="Simplified Tax Invoice",F17="B2B - VAT registered"),"Simplified invoice issued to VAT-registered B2B; ",""))
J18: =IF(A18="","",H18+I18) | O18: =IF(A18="","",SUMPRODUCT((A18>=Setup!$C$19:$C$30)*(A18<=Setup!$D$19:$D$30)*Setup!$A$19:$A$30)) | P18: =IF(A18="","",IF(G18="Standard 15% (Box 1)",ROUND(H18*Setup!$B$9,2),0)) | Q18: =IF(A18="","",I18-P18) | R18: =IF(A18="","",IF(O18=0,"Outside audit periods; ","")&IF(G18="","No VAT category; ","")&IF(ABS(Q18)>Setup!$B$10,"VAT ≠ 15% × net; ","")&IF(AND(F18="B2B - VAT registered",NOT(AND(LEN(E18)=15,LEFT(E18,1)="3",RIGHT(E18,1)="3",ISNUMBER(--E18)))),"Invalid/missing customer VAT no; ","")&IF(L18<>"Yes","Not reported/cleared on FATOORA; ","")&IF(AND(OR(G18="Zero-rated domestic (Box 3)",G18="Export (Box 4)"),N18=""),"Zero-rate/export evidence missing; ","")&IF(AND(C18="Credit Note",H18>0),"Credit note should be negative; ","")&IF(AND(C18="Simplified Tax Invoice",F18="B2B - VAT registered"),"Simplified invoice issued to VAT-registered B2B; ",""))
J19: =IF(A19="","",H19+I19) | O19: =IF(A19="","",SUMPRODUCT((A19>=Setup!$C$19:$C$30)*(A19<=Setup!$D$19:$D$30)*Setup!$A$19:$A$30)) | P19: =IF(A19="","",IF(G19="Standard 15% (Box 1)",ROUND(H19*Setup!$B$9,2),0)) | Q19: =IF(A19="","",I19-P19) | R19: =IF(A19="","",IF(O19=0,"Outside audit periods; ","")&IF(G19="","No VAT category; ","")&IF(ABS(Q19)>Setup!$B$10,"VAT ≠ 15% × net; ","")&IF(AND(F19="B2B - VAT registered",NOT(AND(LEN(E19)=15,LEFT(E19,1)="3",RIGHT(E19,1)="3",ISNUMBER(--E19)))),"Invalid/missing customer VAT no; ","")&IF(L19<>"Yes","Not reported/cleared on FATOORA; ","")&IF(AND(OR(G19="Zero-rated domestic (Box 3)",G19="Export (Box 4)"),N19=""),"Zero-rate/export evidence missing; ","")&IF(AND(C19="Credit Note",H19>0),"Credit note should be negative; ","")&IF(AND(C19="Simplified Tax Invoice",F19="B2B - VAT registered"),"Simplified invoice issued to VAT-registered B2B; ",""))
... J5005: =IF(A5005="","",H5005+I5005) | O5005: =IF(A5005="","",SUMPRODUCT((A5005>=Setup!$C$19:$C$30)*(A5005<=Setup!$D$19:$D$30)*Setup!$A$19:$A$30)) | P5005: =IF(A5005="","",IF(G5005="Standard 15% (Box 1)",ROUND(H5005*Setup!$B$9,2),0)) | Q5005: =IF(A5005="","",I5005-P5005) | R5005: =IF(A5005="","",IF(O5005=0,"Outside audit periods; ","")&IF(G5005="","No VAT category; ","")&IF(ABS(Q5005)>Setup!$B$10,"VAT ≠ 15% × net; ","")&IF(AND(F5005="B2B - VAT registered",NOT(AND(LEN(E5005)=15,LEFT(E5005,1)="3",RIGHT(E5005,1)="3",ISNUMBER(--E5005)))),"Invalid/missing customer VAT no; ","")&IF(L5005<>"Yes","Not reported/cleared on FATOORA; ","")&IF(AND(OR(G5005="Zero-rated domestic (Box 3)",G5005="Export (Box 4)"),N5005=""),"Zero-rate/export evidence missing; ","")&IF(AND(C5005="Credit Note",H5005>0),"Credit note should be negative; ","")&IF(AND(C5005="Simplified Tax Invoice",F5005="B2B - VAT registered"),"Simplified invoice issued to VAT-registered B2B; ",""))

Sheet Purchase_Register
A1: Purchase Register – invoice level (سجل المشتريات)
A2: Every invoice / customs declaration on which input VAT exists. Grey columns test whether the input VAT is defensible in an inspection.
A3: Rows flagged: | B3: =SUMPRODUCT((A6:A5005<>"")*(LEN(U6:U5005)>0)) | C3: VAT at risk (SAR): | D3: =SUM(T6:T5005)
A5: Invoice Date | B5: Supplier Invoice No | C5: Supplier Name | D5: Supplier VAT No | E5: Supplier Country | F5: VAT Category | G5: Expense Nature | H5: Net Amount (SAR) | I5: VAT Amount (SAR) | J5: Total (SAR) | K5: Valid Tax Invoice / Customs Decl. Held? | L5: Input VAT Claimed in Return? | M5: Customs Declaration No (Bayan) | N5: GL Account | O5: Period # | P5: Expected VAT | Q5: VAT Difference | R5: VAT Claimed | S5: Defensible VAT | T5: VAT at Risk | U5: Exceptions / Flags
A6: 45667 | B6: SUP-778 | C6: Al Noor Supplies | D6: 310123456700003 | E6: Saudi Arabia | F6: Standard domestic 15% (Box 7) | G6: General business expense | H6: 40000 | I6: 6000 | J6: =IF(A6="","",H6+I6) | K6: Yes | L6: Yes | N6: 5100 | O6: =IF(A6="","",SUMPRODUCT((A6>=Setup!$C$19:$C$30)*(A6<=Setup!$D$19:$D$30)*Setup!$A$19:$A$30)) | P6: =IF(A6="","",IF(OR(F6="Standard domestic 15% (Box 7)",F6="Import - VAT paid at customs (Box 8)",F6="Import - Reverse charge (Box 9)"),ROUND(H6*Setup!$B$9,2),0)) | Q6: =IF(A6="","",I6-P6) | R6: =IF(A6="","",IF(L6="Yes",I6,0)) | S6: =IF(A6="","",IF(AND(L6="Yes",K6="Yes",NOT(ISNUMBER(SEARCH("blocked",G6))),OR(F6="Standard domestic 15% (Box 7)",F6="Import - VAT paid at customs (Box 8)",F6="Import - Reverse charge (Box 9)"),OR(F6<>"Standard domestic 15% (Box 7)",AND(LEN(D6)=15,LEFT(D6,1)="3",RIGHT(D6,1)="3",ISNUMBER(--D6)))),I6,0)) | T6: =IF(A6="","",R6-S6) | U6: =IF(A6="","",IF(O6=0,"Outside audit periods; ","")&IF(F6="","No VAT category; ","")&IF(ABS(Q6)>Setup!$B$10,"VAT ≠ 15% × net; ","")&IF(AND(F6="Standard domestic 15% (Box 7)",NOT(AND(LEN(D6)=15,LEFT(D6,1)="3",RIGHT(D6,1)="3",ISNUMBER(--D6)))),"Invalid/missing supplier VAT no; ","")&IF(AND(L6="Yes",K6<>"Yes"),"VAT claimed without valid tax invoice; ","")&IF(AND(L6="Yes",ISNUMBER(SEARCH("blocked",G6))),"Blocked input VAT claimed; ","")&IF(AND(F6="Import - VAT paid at customs (Box 8)",M6=""),"Customs declaration no missing; ","")&IF(AND(F6="Import - Reverse charge (Box 9)",E6="Saudi Arabia"),"RCM used for a local supplier; ","")&IF(AND(L6="Yes",NOT(OR(F6="Standard domestic 15% (Box 7)",F6="Import - VAT paid at customs (Box 8)",F6="Import - Reverse charge (Box 9)"))),"VAT claimed on non-taxable category; ",""))
A7: 45682 | B7: FX-2025-01 | C7: Global Consulting Ltd | E7: United Kingdom | F7: Import - Reverse charge (Box 9) | G7: General business expense | H7: 10000 | I7: 1500 | J7: =IF(A7="","",H7+I7) | K7: Yes | L7: Yes | N7: 6100 | O7: =IF(A7="","",SUMPRODUCT((A7>=Setup!$C$19:$C$30)*(A7<=Setup!$D$19:$D$30)*Setup!$A$19:$A$30)) | P7: =IF(A7="","",IF(OR(F7="Standard domestic 15% (Box 7)",F7="Import - VAT paid at customs (Box 8)",F7="Import - Reverse charge (Box 9)"),ROUND(H7*Setup!$B$9,2),0)) | Q7: =IF(A7="","",I7-P7) | R7: =IF(A7="","",IF(L7="Yes",I7,0)) | S7: =IF(A7="","",IF(AND(L7="Yes",K7="Yes",NOT(ISNUMBER(SEARCH("blocked",G7))),OR(F7="Standard domestic 15% (Box 7)",F7="Import - VAT paid at customs (Box 8)",F7="Import - Reverse charge (Box 9)"),OR(F7<>"Standard domestic 15% (Box 7)",AND(LEN(D7)=15,LEFT(D7,1)="3",RIGHT(D7,1)="3",ISNUMBER(--D7)))),I7,0)) | T7: =IF(A7="","",R7-S7) | U7: =IF(A7="","",IF(O7=0,"Outside audit periods; ","")&IF(F7="","No VAT category; ","")&IF(ABS(Q7)>Setup!$B$10,"VAT ≠ 15% × net; ","")&IF(AND(F7="Standard domestic 15% (Box 7)",NOT(AND(LEN(D7)=15,LEFT(D7,1)="3",RIGHT(D7,1)="3",ISNUMBER(--D7)))),"Invalid/missing supplier VAT no; ","")&IF(AND(L7="Yes",K7<>"Yes"),"VAT claimed without valid tax invoice; ","")&IF(AND(L7="Yes",ISNUMBER(SEARCH("blocked",G7))),"Blocked input VAT claimed; ","")&IF(AND(F7="Import - VAT paid at customs (Box 8)",M7=""),"Customs declaration no missing; ","")&IF(AND(F7="Import - Reverse charge (Box 9)",E7="Saudi Arabia"),"RCM used for a local supplier; ","")&IF(AND(L7="Yes",NOT(OR(F7="Standard domestic 15% (Box 7)",F7="Import - VAT paid at customs (Box 8)",F7="Import - Reverse charge (Box 9)"))),"VAT claimed on non-taxable category; ",""))
J8: =IF(A8="","",H8+I8) | O8: =IF(A8="","",SUMPRODUCT((A8>=Setup!$C$19:$C$30)*(A8<=Setup!$D$19:$D$30)*Setup!$A$19:$A$30)) | P8: =IF(A8="","",IF(OR(F8="Standard domestic 15% (Box 7)",F8="Import - VAT paid at customs (Box 8)",F8="Import - Reverse charge (Box 9)"),ROUND(H8*Setup!$B$9,2),0)) | Q8: =IF(A8="","",I8-P8) | R8: =IF(A8="","",IF(L8="Yes",I8,0)) | S8: =IF(A8="","",IF(AND(L8="Yes",K8="Yes",NOT(ISNUMBER(SEARCH("blocked",G8))),OR(F8="Standard domestic 15% (Box 7)",F8="Import - VAT paid at customs (Box 8)",F8="Import - Reverse charge (Box 9)"),OR(F8<>"Standard domestic 15% (Box 7)",AND(LEN(D8)=15,LEFT(D8,1)="3",RIGHT(D8,1)="3",ISNUMBER(--D8)))),I8,0)) | T8: =IF(A8="","",R8-S8) | U8: =IF(A8="","",IF(O8=0,"Outside audit periods; ","")&IF(F8="","No VAT category; ","")&IF(ABS(Q8)>Setup!$B$10,"VAT ≠ 15% × net; ","")&IF(AND(F8="Standard domestic 15% (Box 7)",NOT(AND(LEN(D8)=15,LEFT(D8,1)="3",RIGHT(D8,1)="3",ISNUMBER(--D8)))),"Invalid/missing supplier VAT no; ","")&IF(AND(L8="Yes",K8<>"Yes"),"VAT claimed without valid tax invoice; ","")&IF(AND(L8="Yes",ISNUMBER(SEARCH("blocked",G8))),"Blocked input VAT claimed; ","")&IF(AND(F8="Import - VAT paid at customs (Box 8)",M8=""),"Customs declaration no missing; ","")&IF(AND(F8="Import - Reverse charge (Box 9)",E8="Saudi Arabia"),"RCM used for a local supplier; ","")&IF(AND(L8="Yes",NOT(OR(F8="Standard domestic 15% (Box 7)",F8="Import - VAT paid at customs (Box 8)",F8="Import - Reverse charge (Box 9)"))),"VAT claimed on non-taxable category; ",""))
J9: =IF(A9="","",H9+I9) | O9: =IF(A9="","",SUMPRODUCT((A9>=Setup!$C$19:$C$30)*(A9<=Setup!$D$19:$D$30)*Setup!$A$19:$A$30)) | P9: =IF(A9="","",IF(OR(F9="Standard domestic 15% (Box 7)",F9="Import - VAT paid at customs (Box 8)",F9="Import - Reverse charge (Box 9)"),ROUND(H9*Setup!$B$9,2),0)) | Q9: =IF(A9="","",I9-P9) | R9: =IF(A9="","",IF(L9="Yes",I9,0)) | S9: =IF(A9="","",IF(AND(L9="Yes",K9="Yes",NOT(ISNUMBER(SEARCH("blocked",G9))),OR(F9="Standard domestic 15% (Box 7)",F9="Import - VAT paid at customs (Box 8)",F9="Import - Reverse charge (Box 9)"),OR(F9<>"Standard domestic 15% (Box 7)",AND(LEN(D9)=15,LEFT(D9,1)="3",RIGHT(D9,1)="3",ISNUMBER(--D9)))),I9,0)) | T9: =IF(A9="","",R9-S9) | U9: =IF(A9="","",IF(O9=0,"Outside audit periods; ","")&IF(F9="","No VAT category; ","")&IF(ABS(Q9)>Setup!$B$10,"VAT ≠ 15% × net; ","")&IF(AND(F9="Standard domestic 15% (Box 7)",NOT(AND(LEN(D9)=15,LEFT(D9,1)="3",RIGHT(D9,1)="3",ISNUMBER(--D9)))),"Invalid/missing supplier VAT no; ","")&IF(AND(L9="Yes",K9<>"Yes"),"VAT claimed without valid tax invoice; ","")&IF(AND(L9="Yes",ISNUMBER(SEARCH("blocked",G9))),"Blocked input VAT claimed; ","")&IF(AND(F9="Import - VAT paid at customs (Box 8)",M9=""),"Customs declaration no missing; ","")&IF(AND(F9="Import - Reverse charge (Box 9)",E9="Saudi Arabia"),"RCM used for a local supplier; ","")&IF(AND(L9="Yes",NOT(OR(F9="Standard domestic 15% (Box 7)",F9="Import - VAT paid at customs (Box 8)",F9="Import - Reverse charge (Box 9)"))),"VAT claimed on non-taxable category; ",""))
J10: =IF(A10="","",H10+I10) | O10: =IF(A10="","",SUMPRODUCT((A10>=Setup!$C$19:$C$30)*(A10<=Setup!$D$19:$D$30)*Setup!$A$19:$A$30)) | P10: =IF(A10="","",IF(OR(F10="Standard domestic 15% (Box 7)",F10="Import - VAT paid at customs (Box 8)",F10="Import - Reverse charge (Box 9)"),ROUND(H10*Setup!$B$9,2),0)) | Q10: =IF(A10="","",I10-P10) | R10: =IF(A10="","",IF(L10="Yes",I10,0)) | S10: =IF(A10="","",IF(AND(L10="Yes",K10="Yes",NOT(ISNUMBER(SEARCH("blocked",G10))),OR(F10="Standard domestic 15% (Box 7)",F10="Import - VAT paid at customs (Box 8)",F10="Import - Reverse charge (Box 9)"),OR(F10<>"Standard domestic 15% (Box 7)",AND(LEN(D10)=15,LEFT(D10,1)="3",RIGHT(D10,1)="3",ISNUMBER(--D10)))),I10,0)) | T10: =IF(A10="","",R10-S10) | U10: =IF(A10="","",IF(O10=0,"Outside audit periods; ","")&IF(F10="","No VAT category; ","")&IF(ABS(Q10)>Setup!$B$10,"VAT ≠ 15% × net; ","")&IF(AND(F10="Standard domestic 15% (Box 7)",NOT(AND(LEN(D10)=15,LEFT(D10,1)="3",RIGHT(D10,1)="3",ISNUMBER(--D10)))),"Invalid/missing supplier VAT no; ","")&IF(AND(L10="Yes",K10<>"Yes"),"VAT claimed without valid tax invoice; ","")&IF(AND(L10="Yes",ISNUMBER(SEARCH("blocked",G10))),"Blocked input VAT claimed; ","")&IF(AND(F10="Import - VAT paid at customs (Box 8)",M10=""),"Customs declaration no missing; ","")&IF(AND(F10="Import - Reverse charge (Box 9)",E10="Saudi Arabia"),"RCM used for a local supplier; ","")&IF(AND(L10="Yes",NOT(OR(F10="Standard domestic 15% (Box 7)",F10="Import - VAT paid at customs (Box 8)",F10="Import - Reverse charge (Box 9)"))),"VAT claimed on non-taxable category; ",""))
J11: =IF(A11="","",H11+I11) | O11: =IF(A11="","",SUMPRODUCT((A11>=Setup!$C$19:$C$30)*(A11<=Setup!$D$19:$D$30)*Setup!$A$19:$A$30)) | P11: =IF(A11="","",IF(OR(F11="Standard domestic 15% (Box 7)",F11="Import - VAT paid at customs (Box 8)",F11="Import - Reverse charge (Box 9)"),ROUND(H11*Setup!$B$9,2),0)) | Q11: =IF(A11="","",I11-P11) | R11: =IF(A11="","",IF(L11="Yes",I11,0)) | S11: =IF(A11="","",IF(AND(L11="Yes",K11="Yes",NOT(ISNUMBER(SEARCH("blocked",G11))),OR(F11="Standard domestic 15% (Box 7)",F11="Import - VAT paid at customs (Box 8)",F11="Import - Reverse charge (Box 9)"),OR(F11<>"Standard domestic 15% (Box 7)",AND(LEN(D11)=15,LEFT(D11,1)="3",RIGHT(D11,1)="3",ISNUMBER(--D11)))),I11,0)) | T11: =IF(A11="","",R11-S11) | U11: =IF(A11="","",IF(O11=0,"Outside audit periods; ","")&IF(F11="","No VAT category; ","")&IF(ABS(Q11)>Setup!$B$10,"VAT ≠ 15% × net; ","")&IF(AND(F11="Standard domestic 15% (Box 7)",NOT(AND(LEN(D11)=15,LEFT(D11,1)="3",RIGHT(D11,1)="3",ISNUMBER(--D11)))),"Invalid/missing supplier VAT no; ","")&IF(AND(L11="Yes",K11<>"Yes"),"VAT claimed without valid tax invoice; ","")&IF(AND(L11="Yes",ISNUMBER(SEARCH("blocked",G11))),"Blocked input VAT claimed; ","")&IF(AND(F11="Import - VAT paid at customs (Box 8)",M11=""),"Customs declaration no missing; ","")&IF(AND(F11="Import - Reverse charge (Box 9)",E11="Saudi Arabia"),"RCM used for a local supplier; ","")&IF(AND(L11="Yes",NOT(OR(F11="Standard domestic 15% (Box 7)",F11="Import - VAT paid at customs (Box 8)",F11="Import - Reverse charge (Box 9)"))),"VAT claimed on non-taxable category; ",""))
J12: =IF(A12="","",H12+I12) | O12: =IF(A12="","",SUMPRODUCT((A12>=Setup!$C$19:$C$30)*(A12<=Setup!$D$19:$D$30)*Setup!$A$19:$A$30)) | P12: =IF(A12="","",IF(OR(F12="Standard domestic 15% (Box 7)",F12="Import - VAT paid at customs (Box 8)",F12="Import - Reverse charge (Box 9)"),ROUND(H12*Setup!$B$9,2),0)) | Q12: =IF(A12="","",I12-P12) | R12: =IF(A12="","",IF(L12="Yes",I12,0)) | S12: =IF(A12="","",IF(AND(L12="Yes",K12="Yes",NOT(ISNUMBER(SEARCH("blocked",G12))),OR(F12="Standard domestic 15% (Box 7)",F12="Import - VAT paid at customs (Box 8)",F12="Import - Reverse charge (Box 9)"),OR(F12<>"Standard domestic 15% (Box 7)",AND(LEN(D12)=15,LEFT(D12,1)="3",RIGHT(D12,1)="3",ISNUMBER(--D12)))),I12,0)) | T12: =IF(A12="","",R12-S12) | U12: =IF(A12="","",IF(O12=0,"Outside audit periods; ","")&IF(F12="","No VAT category; ","")&IF(ABS(Q12)>Setup!$B$10,"VAT ≠ 15% × net; ","")&IF(AND(F12="Standard domestic 15% (Box 7)",NOT(AND(LEN(D12)=15,LEFT(D12,1)="3",RIGHT(D12,1)="3",ISNUMBER(--D12)))),"Invalid/missing supplier VAT no; ","")&IF(AND(L12="Yes",K12<>"Yes"),"VAT claimed without valid tax invoice; ","")&IF(AND(L12="Yes",ISNUMBER(SEARCH("blocked",G12))),"Blocked input VAT claimed; ","")&IF(AND(F12="Import - VAT paid at customs (Box 8)",M12=""),"Customs declaration no missing; ","")&IF(AND(F12="Import - Reverse charge (Box 9)",E12="Saudi Arabia"),"RCM used for a local supplier; ","")&IF(AND(L12="Yes",NOT(OR(F12="Standard domestic 15% (Box 7)",F12="Import - VAT paid at customs (Box 8)",F12="Import - Reverse charge (Box 9)"))),"VAT claimed on non-taxable category; ",""))
J13: =IF(A13="","",H13+I13) | O13: =IF(A13="","",SUMPRODUCT((A13>=Setup!$C$19:$C$30)*(A13<=Setup!$D$19:$D$30)*Setup!$A$19:$A$30)) | P13: =IF(A13="","",IF(OR(F13="Standard domestic 15% (Box 7)",F13="Import - VAT paid at customs (Box 8)",F13="Import - Reverse charge (Box 9)"),ROUND(H13*Setup!$B$9,2),0)) | Q13: =IF(A13="","",I13-P13) | R13: =IF(A13="","",IF(L13="Yes",I13,0)) | S13: =IF(A13="","",IF(AND(L13="Yes",K13="Yes",NOT(ISNUMBER(SEARCH("blocked",G13))),OR(F13="Standard domestic 15% (Box 7)",F13="Import - VAT paid at customs (Box 8)",F13="Import - Reverse charge (Box 9)"),OR(F13<>"Standard domestic 15% (Box 7)",AND(LEN(D13)=15,LEFT(D13,1)="3",RIGHT(D13,1)="3",ISNUMBER(--D13)))),I13,0)) | T13: =IF(A13="","",R13-S13) | U13: =IF(A13="","",IF(O13=0,"Outside audit periods; ","")&IF(F13="","No VAT category; ","")&IF(ABS(Q13)>Setup!$B$10,"VAT ≠ 15% × net; ","")&IF(AND(F13="Standard domestic 15% (Box 7)",NOT(AND(LEN(D13)=15,LEFT(D13,1)="3",RIGHT(D13,1)="3",ISNUMBER(--D13)))),"Invalid/missing supplier VAT no; ","")&IF(AND(L13="Yes",K13<>"Yes"),"VAT claimed without valid tax invoice; ","")&IF(AND(L13="Yes",ISNUMBER(SEARCH("blocked",G13))),"Blocked input VAT claimed; ","")&IF(AND(F13="Import - VAT paid at customs (Box 8)",M13=""),"Customs declaration no missing; ","")&IF(AND(F13="Import - Reverse charge (Box 9)",E13="Saudi Arabia"),"RCM used for a local supplier; ","")&IF(AND(L13="Yes",NOT(OR(F13="Standard domestic 15% (Box 7)",F13="Import - VAT paid at customs (Box 8)",F13="Import - Reverse charge (Box 9)"))),"VAT claimed on non-taxable category; ",""))
J14: =IF(A14="","",H14+I14) | O14: =IF(A14="","",SUMPRODUCT((A14>=Setup!$C$19:$C$30)*(A14<=Setup!$D$19:$D$30)*Setup!$A$19:$A$30)) | P14: =IF(A14="","",IF(OR(F14="Standard domestic 15% (Box 7)",F14="Import - VAT paid at customs (Box 8)",F14="Import - Reverse charge (Box 9)"),ROUND(H14*Setup!$B$9,2),0)) | Q14: =IF(A14="","",I14-P14) | R14: =IF(A14="","",IF(L14="Yes",I14,0)) | S14: =IF(A14="","",IF(AND(L14="Yes",K14="Yes",NOT(ISNUMBER(SEARCH("blocked",G14))),OR(F14="Standard domestic 15% (Box 7)",F14="Import - VAT paid at customs (Box 8)",F14="Import - Reverse charge (Box 9)"),OR(F14<>"Standard domestic 15% (Box 7)",AND(LEN(D14)=15,LEFT(D14,1)="3",RIGHT(D14,1)="3",ISNUMBER(--D14)))),I14,0)) | T14: =IF(A14="","",R14-S14) | U14: =IF(A14="","",IF(O14=0,"Outside audit periods; ","")&IF(F14="","No VAT category; ","")&IF(ABS(Q14)>Setup!$B$10,"VAT ≠ 15% × net; ","")&IF(AND(F14="Standard domestic 15% (Box 7)",NOT(AND(LEN(D14)=15,LEFT(D14,1)="3",RIGHT(D14,1)="3",ISNUMBER(--D14)))),"Invalid/missing supplier VAT no; ","")&IF(AND(L14="Yes",K14<>"Yes"),"VAT claimed without valid tax invoice; ","")&IF(AND(L14="Yes",ISNUMBER(SEARCH("blocked",G14))),"Blocked input VAT claimed; ","")&IF(AND(F14="Import - VAT paid at customs (Box 8)",M14=""),"Customs declaration no missing; ","")&IF(AND(F14="Import - Reverse charge (Box 9)",E14="Saudi Arabia"),"RCM used for a local supplier; ","")&IF(AND(L14="Yes",NOT(OR(F14="Standard domestic 15% (Box 7)",F14="Import - VAT paid at customs (Box 8)",F14="Import - Reverse charge (Box 9)"))),"VAT claimed on non-taxable category; ",""))
J15: =IF(A15="","",H15+I15) | O15: =IF(A15="","",SUMPRODUCT((A15>=Setup!$C$19:$C$30)*(A15<=Setup!$D$19:$D$30)*Setup!$A$19:$A$30)) | P15: =IF(A15="","",IF(OR(F15="Standard domestic 15% (Box 7)",F15="Import - VAT paid at customs (Box 8)",F15="Import - Reverse charge (Box 9)"),ROUND(H15*Setup!$B$9,2),0)) | Q15: =IF(A15="","",I15-P15) | R15: =IF(A15="","",IF(L15="Yes",I15,0)) | S15: =IF(A15="","",IF(AND(L15="Yes",K15="Yes",NOT(ISNUMBER(SEARCH("blocked",G15))),OR(F15="Standard domestic 15% (Box 7)",F15="Import - VAT paid at customs (Box 8)",F15="Import - Reverse charge (Box 9)"),OR(F15<>"Standard domestic 15% (Box 7)",AND(LEN(D15)=15,LEFT(D15,1)="3",RIGHT(D15,1)="3",ISNUMBER(--D15)))),I15,0)) | T15: =IF(A15="","",R15-S15) | U15: =IF(A15="","",IF(O15=0,"Outside audit periods; ","")&IF(F15="","No VAT category; ","")&IF(ABS(Q15)>Setup!$B$10,"VAT ≠ 15% × net; ","")&IF(AND(F15="Standard domestic 15% (Box 7)",NOT(AND(LEN(D15)=15,LEFT(D15,1)="3",RIGHT(D15,1)="3",ISNUMBER(--D15)))),"Invalid/missing supplier VAT no; ","")&IF(AND(L15="Yes",K15<>"Yes"),"VAT claimed without valid tax invoice; ","")&IF(AND(L15="Yes",ISNUMBER(SEARCH("blocked",G15))),"Blocked input VAT claimed; ","")&IF(AND(F15="Import - VAT paid at customs (Box 8)",M15=""),"Customs declaration no missing; ","")&IF(AND(F15="Import - Reverse charge (Box 9)",E15="Saudi Arabia"),"RCM used for a local supplier; ","")&IF(AND(L15="Yes",NOT(OR(F15="Standard domestic 15% (Box 7)",F15="Import - VAT paid at customs (Box 8)",F15="Import - Reverse charge (Box 9)"))),"VAT claimed on non-taxable category; ",""))
J16: =IF(A16="","",H16+I16) | O16: =IF(A16="","",SUMPRODUCT((A16>=Setup!$C$19:$C$30)*(A16<=Setup!$D$19:$D$30)*Setup!$A$19:$A$30)) | P16: =IF(A16="","",IF(OR(F16="Standard domestic 15% (Box 7)",F16="Import - VAT paid at customs (Box 8)",F16="Import - Reverse charge (Box 9)"),ROUND(H16*Setup!$B$9,2),0)) | Q16: =IF(A16="","",I16-P16) | R16: =IF(A16="","",IF(L16="Yes",I16,0)) | S16: =IF(A16="","",IF(AND(L16="Yes",K16="Yes",NOT(ISNUMBER(SEARCH("blocked",G16))),OR(F16="Standard domestic 15% (Box 7)",F16="Import - VAT paid at customs (Box 8)",F16="Import - Reverse charge (Box 9)"),OR(F16<>"Standard domestic 15% (Box 7)",AND(LEN(D16)=15,LEFT(D16,1)="3",RIGHT(D16,1)="3",ISNUMBER(--D16)))),I16,0)) | T16: =IF(A16="","",R16-S16) | U16: =IF(A16="","",IF(O16=0,"Outside audit periods; ","")&IF(F16="","No VAT category; ","")&IF(ABS(Q16)>Setup!$B$10,"VAT ≠ 15% × net; ","")&IF(AND(F16="Standard domestic 15% (Box 7)",NOT(AND(LEN(D16)=15,LEFT(D16,1)="3",RIGHT(D16,1)="3",ISNUMBER(--D16)))),"Invalid/missing supplier VAT no; ","")&IF(AND(L16="Yes",K16<>"Yes"),"VAT claimed without valid tax invoice; ","")&IF(AND(L16="Yes",ISNUMBER(SEARCH("blocked",G16))),"Blocked input VAT claimed; ","")&IF(AND(F16="Import - VAT paid at customs (Box 8)",M16=""),"Customs declaration no missing; ","")&IF(AND(F16="Import - Reverse charge (Box 9)",E16="Saudi Arabia"),"RCM used for a local supplier; ","")&IF(AND(L16="Yes",NOT(OR(F16="Standard domestic 15% (Box 7)",F16="Import - VAT paid at customs (Box 8)",F16="Import - Reverse charge (Box 9)"))),"VAT claimed on non-taxable category; ",""))
